/blue/boucher/suhashidesilva/Latest/ONeSAMP_3.1
c0706a-s4.ufhpc
Tue Jun 17 18:27:33 EDT 2025
Python path: /blue/boucher/suhashidesilva/conda_envs/my_env/bin/python
0.60.0
/tmp/slurmd/job5518308/slurm_script: line 28: 
module load conda/25.3.1
source activate /blue/boucher/suhashidesilva/conda_envs/my_env

which python
python -c "import numba; print(numba.__version__)"
: No such file or directory
Running plot script on multiple CPU cores
concurrent.futures.process._RemoteTraceback: 
"""
Traceback (most recent call last):
  File "/blue/boucher/suhashidesilva/conda_envs/my_env/lib/python3.9/concurrent/futures/process.py", line 246, in _process_worker
    r = call_item.fn(*call_item.args, **call_item.kwargs)
  File "/blue/boucher/suhashidesilva/conda_envs/my_env/lib/python3.9/concurrent/futures/process.py", line 205, in _process_chunk
    return [fn(*args) for args in chunk]
  File "/blue/boucher/suhashidesilva/conda_envs/my_env/lib/python3.9/concurrent/futures/process.py", line 205, in <listcomp>
    return [fn(*args) for args in chunk]
  File "/blue/boucher/suhashidesilva/Latest/ONeSAMP_3.1/main.py", line 262, in processRandomPopulation
    statistics1_new[x] = refactorFileStatistics.stat1_new
AttributeError: 'statisticsClass' object has no attribute 'stat1_new'
"""

The above exception was the direct cause of the following exception:

Traceback (most recent call last):
  File "/blue/boucher/suhashidesilva/Latest/ONeSAMP_3.1/main.py", line 287, in <module>
    for result in executor.map(processRandomPopulation, range(numOneSampTrials)):
  File "/blue/boucher/suhashidesilva/conda_envs/my_env/lib/python3.9/concurrent/futures/process.py", line 562, in _chain_from_iterable_of_lists
    for element in iterable:
  File "/blue/boucher/suhashidesilva/conda_envs/my_env/lib/python3.9/concurrent/futures/_base.py", line 609, in result_iterator
    yield fs.pop().result()
  File "/blue/boucher/suhashidesilva/conda_envs/my_env/lib/python3.9/concurrent/futures/_base.py", line 446, in result
    return self.__get_result()
  File "/blue/boucher/suhashidesilva/conda_envs/my_env/lib/python3.9/concurrent/futures/_base.py", line 391, in __get_result
    raise self._exception
AttributeError: 'statisticsClass' object has no attribute 'stat1_new'
Processed /blue/boucher/suhashidesilva/Latest/ONeSAMP_3.1/data_70/genePop100x250_1 and saved output to /blue/boucher/suhashidesilva/Latest/ONeSAMP_3.1/output_70/genePop100x250_1
concurrent.futures.process._RemoteTraceback: 
"""
Traceback (most recent call last):
  File "/blue/boucher/suhashidesilva/conda_envs/my_env/lib/python3.9/concurrent/futures/process.py", line 246, in _process_worker
    r = call_item.fn(*call_item.args, **call_item.kwargs)
  File "/blue/boucher/suhashidesilva/conda_envs/my_env/lib/python3.9/concurrent/futures/process.py", line 205, in _process_chunk
    return [fn(*args) for args in chunk]
  File "/blue/boucher/suhashidesilva/conda_envs/my_env/lib/python3.9/concurrent/futures/process.py", line 205, in <listcomp>
    return [fn(*args) for args in chunk]
  File "/blue/boucher/suhashidesilva/Latest/ONeSAMP_3.1/main.py", line 262, in processRandomPopulation
    statistics1_new[x] = refactorFileStatistics.stat1_new
AttributeError: 'statisticsClass' object has no attribute 'stat1_new'
"""

The above exception was the direct cause of the following exception:

Traceback (most recent call last):
  File "/blue/boucher/suhashidesilva/Latest/ONeSAMP_3.1/main.py", line 287, in <module>
    for result in executor.map(processRandomPopulation, range(numOneSampTrials)):
  File "/blue/boucher/suhashidesilva/conda_envs/my_env/lib/python3.9/concurrent/futures/process.py", line 562, in _chain_from_iterable_of_lists
    for element in iterable:
  File "/blue/boucher/suhashidesilva/conda_envs/my_env/lib/python3.9/concurrent/futures/_base.py", line 609, in result_iterator
    yield fs.pop().result()
  File "/blue/boucher/suhashidesilva/conda_envs/my_env/lib/python3.9/concurrent/futures/_base.py", line 446, in result
    return self.__get_result()
  File "/blue/boucher/suhashidesilva/conda_envs/my_env/lib/python3.9/concurrent/futures/_base.py", line 391, in __get_result
    raise self._exception
AttributeError: 'statisticsClass' object has no attribute 'stat1_new'
Processed /blue/boucher/suhashidesilva/Latest/ONeSAMP_3.1/data_70/genePop100x500_1 and saved output to /blue/boucher/suhashidesilva/Latest/ONeSAMP_3.1/output_70/genePop100x500_1
Tue Jun 17 18:36:33 EDT 2025
